Process Process-1:
Traceback (most recent call last):
  File "/usr/lib/python3.6/multiprocessing/process.py", line 258, in _bootstrap
    self.run()
  File "/usr/lib/python3.6/multiprocessing/process.py", line 93, in run
    self._target(*self._args, **self._kwargs)
  File "/home/ubuntu/.local/lib/python3.6/site-packages/airflow/utils/serve_logs.py", line 39, in serve_logs
    flask_app.run(host='0.0.0.0', port=worker_log_server_port)
  File "/home/ubuntu/.local/lib/python3.6/site-packages/flask/app.py", line 990, in run
    run_simple(host, port, self, **options)
  File "/home/ubuntu/.local/lib/python3.6/site-packages/werkzeug/serving.py", line 1052, in run_simple
    inner()
  File "/home/ubuntu/.local/lib/python3.6/site-packages/werkzeug/serving.py", line 1005, in inner
    fd=fd,
  File "/home/ubuntu/.local/lib/python3.6/site-packages/werkzeug/serving.py", line 848, in make_server
    host, port, app, request_handler, passthrough_errors, ssl_context, fd=fd
  File "/home/ubuntu/.local/lib/python3.6/site-packages/werkzeug/serving.py", line 740, in __init__
    HTTPServer.__init__(self, server_address, handler)
  File "/usr/lib/python3.6/socketserver.py", line 456, in __init__
    self.server_bind()
  File "/usr/lib/python3.6/http/server.py", line 136, in server_bind
    socketserver.TCPServer.server_bind(self)
  File "/usr/lib/python3.6/socketserver.py", line 470, in server_bind
    self.socket.bind(self.server_address)
OSError: [Errno 98] Address already in use
Process ForkProcess-2:
Traceback (most recent call last):
  File "/usr/lib/python3.6/multiprocessing/process.py", line 258, in _bootstrap
    self.run()
  File "/usr/lib/python3.6/multiprocessing/process.py", line 93, in run
    self._target(*self._args, **self._kwargs)
  File "/home/ubuntu/.local/lib/python3.6/site-packages/airflow/utils/dag_processing.py", line 370, in _run_processor_manager
    processor_manager.start()
  File "/home/ubuntu/.local/lib/python3.6/site-packages/airflow/utils/dag_processing.py", line 610, in start
    return self._run_parsing_loop()
  File "/home/ubuntu/.local/lib/python3.6/site-packages/airflow/utils/dag_processing.py", line 685, in _run_parsing_loop
    self.prepare_file_path_queue()
  File "/home/ubuntu/.local/lib/python3.6/site-packages/airflow/utils/dag_processing.py", line 1056, in prepare_file_path_queue
    files_with_mtime[file_path] = os.path.getmtime(file_path)
  File "/usr/lib/python3.6/genericpath.py", line 55, in getmtime
    return os.stat(filename).st_mtime
FileNotFoundError: [Errno 2] No such file or directory: '/home/ubuntu/ML_cylynx_nlp/airflow/dags/test_dag.py'
