[2021-05-26 06:26:10,487] {taskinstance.py:876} INFO - Dependencies all met for <TaskInstance: my_simple_dag.greet 2018-09-24T12:10:00+00:00 [queued]>
[2021-05-26 06:26:10,496] {taskinstance.py:876} INFO - Dependencies all met for <TaskInstance: my_simple_dag.greet 2018-09-24T12:10:00+00:00 [queued]>
[2021-05-26 06:26:10,496] {taskinstance.py:1067} INFO - 
--------------------------------------------------------------------------------
[2021-05-26 06:26:10,496] {taskinstance.py:1068} INFO - Starting attempt 1 of 1
[2021-05-26 06:26:10,496] {taskinstance.py:1069} INFO - 
--------------------------------------------------------------------------------
[2021-05-26 06:26:10,515] {taskinstance.py:1087} INFO - Executing <Task(PythonOperator): greet> on 2018-09-24T12:10:00+00:00
[2021-05-26 06:26:10,517] {standard_task_runner.py:52} INFO - Started process 20516 to run task
[2021-05-26 06:26:10,533] {standard_task_runner.py:76} INFO - Running: ['airflow', 'tasks', 'run', 'my_simple_dag', 'greet', '2018-09-24T12:10:00+00:00', '--job-id', '34', '--pool', 'default_pool', '--raw', '--subdir', 'DAGS_FOLDER/test_dag.py', '--cfg-path', '/tmp/tmpbkfwr91q', '--error-file', '/tmp/tmps_10j67y']
[2021-05-26 06:26:10,535] {standard_task_runner.py:77} INFO - Job 34: Subtask greet
[2021-05-26 06:26:10,590] {logging_mixin.py:104} INFO - Running <TaskInstance: my_simple_dag.greet 2018-09-24T12:10:00+00:00 [running]> on host nus-fintech-ner-1.asia-southeast1-b.c.cylynx-dev-badc.internal
[2021-05-26 06:26:10,658] {taskinstance.py:1282} INFO - Exporting the following env vars:
AIRFLOW_CTX_DAG_OWNER=airflow
AIRFLOW_CTX_DAG_ID=my_simple_dag
AIRFLOW_CTX_TASK_ID=greet
AIRFLOW_CTX_EXECUTION_DATE=2018-09-24T12:10:00+00:00
AIRFLOW_CTX_DAG_RUN_ID=scheduled__2018-09-24T12:10:00+00:00
[2021-05-26 06:26:10,659] {logging_mixin.py:104} INFO - Writing in file
[2021-05-26 06:26:10,660] {taskinstance.py:1481} ERROR - Task failed with exception
Traceback (most recent call last):
  File "/home/ubuntu/.local/lib/python3.6/site-packages/airflow/models/taskinstance.py", line 1137, in _run_raw_task
    self._prepare_and_execute_task_with_callbacks(context, task)
  File "/home/ubuntu/.local/lib/python3.6/site-packages/airflow/models/taskinstance.py", line 1311, in _prepare_and_execute_task_with_callbacks
    result = self._execute_task(context, task_copy)
  File "/home/ubuntu/.local/lib/python3.6/site-packages/airflow/models/taskinstance.py", line 1341, in _execute_task
    result = task_copy.execute(context=context)
  File "/home/ubuntu/.local/lib/python3.6/site-packages/airflow/operators/python.py", line 150, in execute
    return_value = self.execute_callable()
  File "/home/ubuntu/.local/lib/python3.6/site-packages/airflow/operators/python.py", line 161, in execute_callable
    return self.python_callable(*self.op_args, **self.op_kwargs)
  File "/home/ubuntu/ML_cylynx_nlp/airflow/dags/test_dag.py", line 10, in greet
    with open('path/to/file/greet.txt', 'a+', encoding='utf8') as f:
FileNotFoundError: [Errno 2] No such file or directory: 'path/to/file/greet.txt'
[2021-05-26 06:26:10,662] {taskinstance.py:1531} INFO - Marking task as FAILED. dag_id=my_simple_dag, task_id=greet, execution_date=20180924T121000, start_date=20210526T062610, end_date=20210526T062610
[2021-05-26 06:26:10,703] {local_task_job.py:151} INFO - Task exited with return code 1
